2019-08-15 15:00:22 [django.request:228] [WARNING] - Not Found: /
2019-08-15 15:00:22 [django.request:228] [WARNING] - Not Found: /favicon.ico
2019-08-15 15:00:35 [django.request:228] [ERROR] - Internal Server Error: /api/tree/
Traceback (most recent call last):
  File "/Users/huoyinghui/workspaces/drf3_opsweb/lib/python3.6/site-packages/django/core/handlers/exception.py", line 34, in inner
    response = get_response(request)
  File "/Users/huoyinghui/workspaces/drf3_opsweb/lib/python3.6/site-packages/django/core/handlers/base.py", line 126, in _get_response
    response = self.process_exception_by_middleware(e, request)
  File "/Users/huoyinghui/workspaces/drf3_opsweb/lib/python3.6/site-packages/django/core/handlers/base.py", line 124, in _get_response
    response = wrapped_callback(request, *callback_args, **callback_kwargs)
  File "/Users/huoyinghui/workspaces/drf3_opsweb/lib/python3.6/site-packages/django/views/decorators/csrf.py", line 54, in wrapped_view
    return view_func(*args, **kwargs)
  File "/Users/huoyinghui/workspaces/drf3_opsweb/lib/python3.6/site-packages/rest_framework/viewsets.py", line 103, in view
    return self.dispatch(request, *args, **kwargs)
  File "/Users/huoyinghui/workspaces/drf3_opsweb/lib/python3.6/site-packages/rest_framework/views.py", line 483, in dispatch
    response = self.handle_exception(exc)
  File "/Users/huoyinghui/workspaces/drf3_opsweb/lib/python3.6/site-packages/rest_framework/views.py", line 443, in handle_exception
    self.raise_uncaught_exception(exc)
  File "/Users/huoyinghui/workspaces/drf3_opsweb/lib/python3.6/site-packages/rest_framework/views.py", line 480, in dispatch
    response = handler(request, *args, **kwargs)
  File "/Users/huoyinghui/github/docker_nginx/opsweb/core/views.py", line 101, in list
    return self.get(request)
  File "/Users/huoyinghui/github/docker_nginx/opsweb/core/views.py", line 101, in list
    return self.get(request)
  File "/Users/huoyinghui/github/docker_nginx/opsweb/core/views.py", line 101, in list
    return self.get(request)
  [Previous line repeated 921 more times]
RecursionError: maximum recursion depth exceeded
2019-08-15 15:01:32 [django.request:228] [ERROR] - Internal Server Error: /api/tree/
Traceback (most recent call last):
  File "/Users/huoyinghui/workspaces/drf3_opsweb/lib/python3.6/site-packages/django/core/handlers/exception.py", line 34, in inner
    response = get_response(request)
  File "/Users/huoyinghui/workspaces/drf3_opsweb/lib/python3.6/site-packages/django/core/handlers/base.py", line 126, in _get_response
    response = self.process_exception_by_middleware(e, request)
  File "/Users/huoyinghui/workspaces/drf3_opsweb/lib/python3.6/site-packages/django/core/handlers/base.py", line 124, in _get_response
    response = wrapped_callback(request, *callback_args, **callback_kwargs)
  File "/Users/huoyinghui/workspaces/drf3_opsweb/lib/python3.6/site-packages/django/views/decorators/csrf.py", line 54, in wrapped_view
    return view_func(*args, **kwargs)
  File "/Users/huoyinghui/workspaces/drf3_opsweb/lib/python3.6/site-packages/rest_framework/viewsets.py", line 103, in view
    return self.dispatch(request, *args, **kwargs)
  File "/Users/huoyinghui/workspaces/drf3_opsweb/lib/python3.6/site-packages/rest_framework/views.py", line 483, in dispatch
    response = self.handle_exception(exc)
  File "/Users/huoyinghui/workspaces/drf3_opsweb/lib/python3.6/site-packages/rest_framework/views.py", line 443, in handle_exception
    self.raise_uncaught_exception(exc)
  File "/Users/huoyinghui/workspaces/drf3_opsweb/lib/python3.6/site-packages/rest_framework/views.py", line 480, in dispatch
    response = handler(request, *args, **kwargs)
  File "/Users/huoyinghui/github/docker_nginx/opsweb/core/views.py", line 101, in list
    return self.get(request)
  File "/Users/huoyinghui/github/docker_nginx/opsweb/core/views.py", line 101, in list
    return self.get(request)
  File "/Users/huoyinghui/github/docker_nginx/opsweb/core/views.py", line 101, in list
    return self.get(request)
  [Previous line repeated 921 more times]
RecursionError: maximum recursion depth exceeded
