2019-07-17 17:45:55 [django.request:228] [WARNING] - Forbidden: /docs/
2019-07-17 17:51:55 [django.request:228] [WARNING] - Forbidden: /docs/
2019-07-17 17:52:19 [django.request:228] [WARNING] - Forbidden: /docs/
2019-07-17 18:16:52 [django.request:228] [WARNING] - Forbidden: /docs/
2019-07-17 18:16:53 [django.request:228] [WARNING] - Forbidden: /docs/
2019-07-25 11:41:03 [django.request:228] [WARNING] - Not Found: /favicon.ico
2019-07-25 11:41:08 [django.request:228] [WARNING] - Forbidden: /docs/
2019-07-25 11:47:04 [django.request:228] [WARNING] - Forbidden: /api-token-auth/
2019-07-25 11:47:18 [django.request:228] [WARNING] - Forbidden: /api-token-auth/
2019-07-25 11:50:39 [django.request:228] [WARNING] - Forbidden: /api-token-auth/
2019-07-25 11:51:06 [django.request:228] [WARNING] - Forbidden: /api-token-auth/
2019-07-25 14:31:19 [django.request:228] [ERROR] - Internal Server Error: /tree/
Traceback (most recent call last):
  File "/Users/huoyinghui/workspaces/drf3_opsweb/lib/python3.6/site-packages/django/core/handlers/exception.py", line 34, in inner
    response = get_response(request)
  File "/Users/huoyinghui/workspaces/drf3_opsweb/lib/python3.6/site-packages/django/core/handlers/base.py", line 126, in _get_response
    response = self.process_exception_by_middleware(e, request)
  File "/Users/huoyinghui/workspaces/drf3_opsweb/lib/python3.6/site-packages/django/core/handlers/base.py", line 124, in _get_response
    response = wrapped_callback(request, *callback_args, **callback_kwargs)
  File "/Users/huoyinghui/github/docker_nginx/opsweb/core/views.py", line 63, in show_genres
    return render(request, "genres.html", {'genres': Genre.objects.all()})
  File "/Users/huoyinghui/workspaces/drf3_opsweb/lib/python3.6/site-packages/django/shortcuts.py", line 36, in render
    content = loader.render_to_string(template_name, context, request, using=using)
  File "/Users/huoyinghui/workspaces/drf3_opsweb/lib/python3.6/site-packages/django/template/loader.py", line 61, in render_to_string
    template = get_template(template_name, using=using)
  File "/Users/huoyinghui/workspaces/drf3_opsweb/lib/python3.6/site-packages/django/template/loader.py", line 19, in get_template
    raise TemplateDoesNotExist(template_name, chain=chain)
django.template.exceptions.TemplateDoesNotExist: genres.html
2019-07-25 15:26:50 [django.request:228] [WARNING] - Not Found: /admin/docs
2019-07-25 15:27:08 [django.request:228] [ERROR] - Internal Server Error: /admin/doc/
Traceback (most recent call last):
  File "/Users/huoyinghui/workspaces/drf3_opsweb/lib/python3.6/site-packages/django/core/handlers/exception.py", line 34, in inner
    response = get_response(request)
  File "/Users/huoyinghui/workspaces/drf3_opsweb/lib/python3.6/site-packages/django/core/handlers/base.py", line 156, in _get_response
    response = self.process_exception_by_middleware(e, request)
  File "/Users/huoyinghui/workspaces/drf3_opsweb/lib/python3.6/site-packages/django/core/handlers/base.py", line 154, in _get_response
    response = response.render()
  File "/Users/huoyinghui/workspaces/drf3_opsweb/lib/python3.6/site-packages/django/template/response.py", line 106, in render
    self.content = self.rendered_content
  File "/Users/huoyinghui/workspaces/drf3_opsweb/lib/python3.6/site-packages/django/template/response.py", line 81, in rendered_content
    template = self.resolve_template(self.template_name)
  File "/Users/huoyinghui/workspaces/drf3_opsweb/lib/python3.6/site-packages/django/template/response.py", line 63, in resolve_template
    return select_template(template, using=self.using)
  File "/Users/huoyinghui/workspaces/drf3_opsweb/lib/python3.6/site-packages/django/template/loader.py", line 47, in select_template
    raise TemplateDoesNotExist(', '.join(template_name_list), chain=chain)
django.template.exceptions.TemplateDoesNotExist: admin_doc/missing_docutils.html
2019-07-25 15:44:52 [django.request:228] [WARNING] - Not Found: /favicon.ico
2019-07-25 15:45:07 [django.request:228] [WARNING] - Not Found: /doc
2019-07-26 10:31:29 [django.request:228] [WARNING] - Not Found: /favicon.ico
2019-07-29 15:29:02 [django.request:228] [WARNING] - Not Found: /favicon.ico
2019-07-29 15:49:22 [django.request:228] [WARNING] - Not Found: /manifest.json
2019-07-29 15:49:22 [django.request:228] [WARNING] - Not Found: /favicon.ico
2019-07-29 15:50:51 [django.request:228] [WARNING] - Not Found: /manifest.json
2019-07-29 15:51:24 [django.request:228] [WARNING] - Not Found: /manifest.json
2019-07-29 15:51:38 [django.request:228] [WARNING] - Not Found: /manifest.json
2019-07-29 15:51:52 [django.request:228] [WARNING] - Not Found: /manifest.json
2019-07-29 15:52:05 [django.request:228] [WARNING] - Not Found: /manifest.json
2019-07-29 16:23:45 [django.request:228] [WARNING] - Not Found: /favicon.ico
2019-07-29 17:44:43 [django.request:228] [WARNING] - Forbidden: /docs/
2019-07-29 17:45:11 [django.request:228] [WARNING] - Unauthorized: /api/core/tree/
2019-07-29 17:47:28 [django.request:228] [WARNING] - Unauthorized: /api/core/tree/
2019-07-29 17:53:32 [django.request:228] [WARNING] - Unauthorized: /api/core/tree/
2019-07-29 18:10:18 [django.request:228] [ERROR] - Internal Server Error: /
Traceback (most recent call last):
  File "/Users/huoyinghui/workspaces/drf3_opsweb/lib/python3.6/site-packages/django/core/handlers/exception.py", line 34, in inner
    response = get_response(request)
  File "/Users/huoyinghui/workspaces/drf3_opsweb/lib/python3.6/site-packages/django/core/handlers/base.py", line 156, in _get_response
    response = self.process_exception_by_middleware(e, request)
  File "/Users/huoyinghui/workspaces/drf3_opsweb/lib/python3.6/site-packages/django/core/handlers/base.py", line 154, in _get_response
    response = response.render()
  File "/Users/huoyinghui/workspaces/drf3_opsweb/lib/python3.6/site-packages/django/template/response.py", line 106, in render
    self.content = self.rendered_content
  File "/Users/huoyinghui/workspaces/drf3_opsweb/lib/python3.6/site-packages/django/template/response.py", line 81, in rendered_content
    template = self.resolve_template(self.template_name)
  File "/Users/huoyinghui/workspaces/drf3_opsweb/lib/python3.6/site-packages/django/template/response.py", line 63, in resolve_template
    return select_template(template, using=self.using)
  File "/Users/huoyinghui/workspaces/drf3_opsweb/lib/python3.6/site-packages/django/template/loader.py", line 47, in select_template
    raise TemplateDoesNotExist(', '.join(template_name_list), chain=chain)
django.template.exceptions.TemplateDoesNotExist: index.html
2019-07-29 18:13:56 [django.request:228] [WARNING] - Not Found: /accounts/profile/
2019-07-29 18:23:50 [django.request:228] [WARNING] - Forbidden: /docs/
2019-07-29 18:35:26 [django.request:228] [ERROR] - Internal Server Error: /
Traceback (most recent call last):
  File "/Users/huoyinghui/workspaces/drf3_opsweb/lib/python3.6/site-packages/django/core/handlers/exception.py", line 34, in inner
    response = get_response(request)
  File "/Users/huoyinghui/workspaces/drf3_opsweb/lib/python3.6/site-packages/django/core/handlers/base.py", line 156, in _get_response
    response = self.process_exception_by_middleware(e, request)
  File "/Users/huoyinghui/workspaces/drf3_opsweb/lib/python3.6/site-packages/django/core/handlers/base.py", line 154, in _get_response
    response = response.render()
  File "/Users/huoyinghui/workspaces/drf3_opsweb/lib/python3.6/site-packages/django/template/response.py", line 106, in render
    self.content = self.rendered_content
  File "/Users/huoyinghui/workspaces/drf3_opsweb/lib/python3.6/site-packages/django/template/response.py", line 81, in rendered_content
    template = self.resolve_template(self.template_name)
  File "/Users/huoyinghui/workspaces/drf3_opsweb/lib/python3.6/site-packages/django/template/response.py", line 63, in resolve_template
    return select_template(template, using=self.using)
  File "/Users/huoyinghui/workspaces/drf3_opsweb/lib/python3.6/site-packages/django/template/loader.py", line 47, in select_template
    raise TemplateDoesNotExist(', '.join(template_name_list), chain=chain)
django.template.exceptions.TemplateDoesNotExist: index.html
2019-07-29 18:35:33 [django.request:228] [ERROR] - Internal Server Error: /xadmin/
Traceback (most recent call last):
  File "/Users/huoyinghui/workspaces/drf3_opsweb/lib/python3.6/site-packages/django/db/backends/utils.py", line 85, in _execute
    return self.cursor.execute(sql, params)
  File "/Users/huoyinghui/workspaces/drf3_opsweb/lib/python3.6/site-packages/django/db/backends/mysql/base.py", line 71, in execute
    return self.cursor.execute(query, args)
  File "/Users/huoyinghui/workspaces/drf3_opsweb/lib/python3.6/site-packages/pymysql/cursors.py", line 170, in execute
    result = self._query(query)
  File "/Users/huoyinghui/workspaces/drf3_opsweb/lib/python3.6/site-packages/pymysql/cursors.py", line 328, in _query
    conn.query(q)
  File "/Users/huoyinghui/workspaces/drf3_opsweb/lib/python3.6/site-packages/pymysql/connections.py", line 516, in query
    self._affected_rows = self._read_query_result(unbuffered=unbuffered)
  File "/Users/huoyinghui/workspaces/drf3_opsweb/lib/python3.6/site-packages/pymysql/connections.py", line 727, in _read_query_result
    result.read()
  File "/Users/huoyinghui/workspaces/drf3_opsweb/lib/python3.6/site-packages/pymysql/connections.py", line 1066, in read
    first_packet = self.connection._read_packet()
  File "/Users/huoyinghui/workspaces/drf3_opsweb/lib/python3.6/site-packages/pymysql/connections.py", line 683, in _read_packet
    packet.check_error()
  File "/Users/huoyinghui/workspaces/drf3_opsweb/lib/python3.6/site-packages/pymysql/protocol.py", line 220, in check_error
    err.raise_mysql_exception(self._data)
  File "/Users/huoyinghui/workspaces/drf3_opsweb/lib/python3.6/site-packages/pymysql/err.py", line 109, in raise_mysql_exception
    raise errorclass(errno, errval)
pymysql.err.ProgrammingError: (1146, "Table 'opsweb.xadmin_usersettings' doesn't exist")

The above exception was the direct cause of the following exception:

Traceback (most recent call last):
  File "/Users/huoyinghui/workspaces/drf3_opsweb/lib/python3.6/site-packages/django/core/handlers/exception.py", line 34, in inner
    response = get_response(request)
  File "/Users/huoyinghui/workspaces/drf3_opsweb/lib/python3.6/site-packages/django/core/handlers/base.py", line 126, in _get_response
    response = self.process_exception_by_middleware(e, request)
  File "/Users/huoyinghui/workspaces/drf3_opsweb/lib/python3.6/site-packages/django/core/handlers/base.py", line 124, in _get_response
    response = wrapped_callback(request, *callback_args, **callback_kwargs)
  File "/Users/huoyinghui/workspaces/drf3_opsweb/lib/python3.6/site-packages/xadmin/sites.py", line 300, in wrapper
    return self.admin_view(view, cacheable)(*args, **kwargs)
  File "/Users/huoyinghui/workspaces/drf3_opsweb/lib/python3.6/site-packages/django/views/decorators/cache.py", line 44, in _wrapped_view_func
    response = view_func(request, *args, **kwargs)
  File "/Users/huoyinghui/workspaces/drf3_opsweb/lib/python3.6/site-packages/xadmin/sites.py", line 208, in inner
    return view(request, *args, **kwargs)
  File "/Users/huoyinghui/workspaces/drf3_opsweb/lib/python3.6/site-packages/xadmin/views/base.py", line 282, in view
    return handler(request, *args, **kwargs)
  File "/Users/huoyinghui/workspaces/drf3_opsweb/lib/python3.6/site-packages/django/views/decorators/cache.py", line 44, in _wrapped_view_func
    response = view_func(request, *args, **kwargs)
  File "/Users/huoyinghui/workspaces/drf3_opsweb/lib/python3.6/site-packages/xadmin/views/dashboard.py", line 592, in get
    self.widgets = self.get_widgets()
  File "/Users/huoyinghui/workspaces/drf3_opsweb/lib/python3.6/site-packages/xadmin/views/base.py", line 80, in method
    return filter_chain(filters, len(filters) - 1, _inner_method, *args, **kwargs)
  File "/Users/huoyinghui/workspaces/drf3_opsweb/lib/python3.6/site-packages/xadmin/views/base.py", line 49, in filter_chain
    return func()
  File "/Users/huoyinghui/workspaces/drf3_opsweb/lib/python3.6/site-packages/xadmin/views/base.py", line 74, in _inner_method
    return func(self, *args, **kwargs)
  File "/Users/huoyinghui/workspaces/drf3_opsweb/lib/python3.6/site-packages/xadmin/views/dashboard.py", line 549, in get_widgets
    if len(portal_pos):
  File "/Users/huoyinghui/workspaces/drf3_opsweb/lib/python3.6/site-packages/django/db/models/query.py", line 250, in __len__
    self._fetch_all()
  File "/Users/huoyinghui/workspaces/drf3_opsweb/lib/python3.6/site-packages/django/db/models/query.py", line 1183, in _fetch_all
    self._result_cache = list(self._iterable_class(self))
  File "/Users/huoyinghui/workspaces/drf3_opsweb/lib/python3.6/site-packages/django/db/models/query.py", line 54, in __iter__
    results = compiler.execute_sql(chunked_fetch=self.chunked_fetch, chunk_size=self.chunk_size)
  File "/Users/huoyinghui/workspaces/drf3_opsweb/lib/python3.6/site-packages/django/db/models/sql/compiler.py", line 1061, in execute_sql
    cursor.execute(sql, params)
  File "/Users/huoyinghui/workspaces/drf3_opsweb/lib/python3.6/site-packages/django/db/backends/utils.py", line 100, in execute
    return super().execute(sql, params)
  File "/Users/huoyinghui/workspaces/drf3_opsweb/lib/python3.6/site-packages/django/db/backends/utils.py", line 68, in execute
    return self._execute_with_wrappers(sql, params, many=False, executor=self._execute)
  File "/Users/huoyinghui/workspaces/drf3_opsweb/lib/python3.6/site-packages/django/db/backends/utils.py", line 77, in _execute_with_wrappers
    return executor(sql, params, many, context)
  File "/Users/huoyinghui/workspaces/drf3_opsweb/lib/python3.6/site-packages/django/db/backends/utils.py", line 85, in _execute
    return self.cursor.execute(sql, params)
  File "/Users/huoyinghui/workspaces/drf3_opsweb/lib/python3.6/site-packages/django/db/utils.py", line 89, in __exit__
    raise dj_exc_value.with_traceback(traceback) from exc_value
  File "/Users/huoyinghui/workspaces/drf3_opsweb/lib/python3.6/site-packages/django/db/backends/utils.py", line 85, in _execute
    return self.cursor.execute(sql, params)
  File "/Users/huoyinghui/workspaces/drf3_opsweb/lib/python3.6/site-packages/django/db/backends/mysql/base.py", line 71, in execute
    return self.cursor.execute(query, args)
  File "/Users/huoyinghui/workspaces/drf3_opsweb/lib/python3.6/site-packages/pymysql/cursors.py", line 170, in execute
    result = self._query(query)
  File "/Users/huoyinghui/workspaces/drf3_opsweb/lib/python3.6/site-packages/pymysql/cursors.py", line 328, in _query
    conn.query(q)
  File "/Users/huoyinghui/workspaces/drf3_opsweb/lib/python3.6/site-packages/pymysql/connections.py", line 516, in query
    self._affected_rows = self._read_query_result(unbuffered=unbuffered)
  File "/Users/huoyinghui/workspaces/drf3_opsweb/lib/python3.6/site-packages/pymysql/connections.py", line 727, in _read_query_result
    result.read()
  File "/Users/huoyinghui/workspaces/drf3_opsweb/lib/python3.6/site-packages/pymysql/connections.py", line 1066, in read
    first_packet = self.connection._read_packet()
  File "/Users/huoyinghui/workspaces/drf3_opsweb/lib/python3.6/site-packages/pymysql/connections.py", line 683, in _read_packet
    packet.check_error()
  File "/Users/huoyinghui/workspaces/drf3_opsweb/lib/python3.6/site-packages/pymysql/protocol.py", line 220, in check_error
    err.raise_mysql_exception(self._data)
  File "/Users/huoyinghui/workspaces/drf3_opsweb/lib/python3.6/site-packages/pymysql/err.py", line 109, in raise_mysql_exception
    raise errorclass(errno, errval)
django.db.utils.ProgrammingError: (1146, "Table 'opsweb.xadmin_usersettings' doesn't exist")
2019-07-29 18:36:11 [django.request:228] [ERROR] - Internal Server Error: /xadmin/
Traceback (most recent call last):
  File "/Users/huoyinghui/workspaces/drf3_opsweb/lib/python3.6/site-packages/django/db/backends/utils.py", line 85, in _execute
    return self.cursor.execute(sql, params)
  File "/Users/huoyinghui/workspaces/drf3_opsweb/lib/python3.6/site-packages/django/db/backends/mysql/base.py", line 71, in execute
    return self.cursor.execute(query, args)
  File "/Users/huoyinghui/workspaces/drf3_opsweb/lib/python3.6/site-packages/pymysql/cursors.py", line 170, in execute
    result = self._query(query)
  File "/Users/huoyinghui/workspaces/drf3_opsweb/lib/python3.6/site-packages/pymysql/cursors.py", line 328, in _query
    conn.query(q)
  File "/Users/huoyinghui/workspaces/drf3_opsweb/lib/python3.6/site-packages/pymysql/connections.py", line 516, in query
    self._affected_rows = self._read_query_result(unbuffered=unbuffered)
  File "/Users/huoyinghui/workspaces/drf3_opsweb/lib/python3.6/site-packages/pymysql/connections.py", line 727, in _read_query_result
    result.read()
  File "/Users/huoyinghui/workspaces/drf3_opsweb/lib/python3.6/site-packages/pymysql/connections.py", line 1066, in read
    first_packet = self.connection._read_packet()
  File "/Users/huoyinghui/workspaces/drf3_opsweb/lib/python3.6/site-packages/pymysql/connections.py", line 683, in _read_packet
    packet.check_error()
  File "/Users/huoyinghui/workspaces/drf3_opsweb/lib/python3.6/site-packages/pymysql/protocol.py", line 220, in check_error
    err.raise_mysql_exception(self._data)
  File "/Users/huoyinghui/workspaces/drf3_opsweb/lib/python3.6/site-packages/pymysql/err.py", line 109, in raise_mysql_exception
    raise errorclass(errno, errval)
pymysql.err.ProgrammingError: (1146, "Table 'opsweb.xadmin_usersettings' doesn't exist")

The above exception was the direct cause of the following exception:

Traceback (most recent call last):
  File "/Users/huoyinghui/workspaces/drf3_opsweb/lib/python3.6/site-packages/django/core/handlers/exception.py", line 34, in inner
    response = get_response(request)
  File "/Users/huoyinghui/workspaces/drf3_opsweb/lib/python3.6/site-packages/django/core/handlers/base.py", line 126, in _get_response
    response = self.process_exception_by_middleware(e, request)
  File "/Users/huoyinghui/workspaces/drf3_opsweb/lib/python3.6/site-packages/django/core/handlers/base.py", line 124, in _get_response
    response = wrapped_callback(request, *callback_args, **callback_kwargs)
  File "/Users/huoyinghui/workspaces/drf3_opsweb/lib/python3.6/site-packages/xadmin/sites.py", line 300, in wrapper
    return self.admin_view(view, cacheable)(*args, **kwargs)
  File "/Users/huoyinghui/workspaces/drf3_opsweb/lib/python3.6/site-packages/django/views/decorators/cache.py", line 44, in _wrapped_view_func
    response = view_func(request, *args, **kwargs)
  File "/Users/huoyinghui/workspaces/drf3_opsweb/lib/python3.6/site-packages/xadmin/sites.py", line 208, in inner
    return view(request, *args, **kwargs)
  File "/Users/huoyinghui/workspaces/drf3_opsweb/lib/python3.6/site-packages/xadmin/views/base.py", line 282, in view
    return handler(request, *args, **kwargs)
  File "/Users/huoyinghui/workspaces/drf3_opsweb/lib/python3.6/site-packages/django/views/decorators/cache.py", line 44, in _wrapped_view_func
    response = view_func(request, *args, **kwargs)
  File "/Users/huoyinghui/workspaces/drf3_opsweb/lib/python3.6/site-packages/xadmin/views/dashboard.py", line 592, in get
    self.widgets = self.get_widgets()
  File "/Users/huoyinghui/workspaces/drf3_opsweb/lib/python3.6/site-packages/xadmin/views/base.py", line 80, in method
    return filter_chain(filters, len(filters) - 1, _inner_method, *args, **kwargs)
  File "/Users/huoyinghui/workspaces/drf3_opsweb/lib/python3.6/site-packages/xadmin/views/base.py", line 49, in filter_chain
    return func()
  File "/Users/huoyinghui/workspaces/drf3_opsweb/lib/python3.6/site-packages/xadmin/views/base.py", line 74, in _inner_method
    return func(self, *args, **kwargs)
  File "/Users/huoyinghui/workspaces/drf3_opsweb/lib/python3.6/site-packages/xadmin/views/dashboard.py", line 549, in get_widgets
    if len(portal_pos):
  File "/Users/huoyinghui/workspaces/drf3_opsweb/lib/python3.6/site-packages/django/db/models/query.py", line 250, in __len__
    self._fetch_all()
  File "/Users/huoyinghui/workspaces/drf3_opsweb/lib/python3.6/site-packages/django/db/models/query.py", line 1183, in _fetch_all
    self._result_cache = list(self._iterable_class(self))
  File "/Users/huoyinghui/workspaces/drf3_opsweb/lib/python3.6/site-packages/django/db/models/query.py", line 54, in __iter__
    results = compiler.execute_sql(chunked_fetch=self.chunked_fetch, chunk_size=self.chunk_size)
  File "/Users/huoyinghui/workspaces/drf3_opsweb/lib/python3.6/site-packages/django/db/models/sql/compiler.py", line 1061, in execute_sql
    cursor.execute(sql, params)
  File "/Users/huoyinghui/workspaces/drf3_opsweb/lib/python3.6/site-packages/django/db/backends/utils.py", line 100, in execute
    return super().execute(sql, params)
  File "/Users/huoyinghui/workspaces/drf3_opsweb/lib/python3.6/site-packages/django/db/backends/utils.py", line 68, in execute
    return self._execute_with_wrappers(sql, params, many=False, executor=self._execute)
  File "/Users/huoyinghui/workspaces/drf3_opsweb/lib/python3.6/site-packages/django/db/backends/utils.py", line 77, in _execute_with_wrappers
    return executor(sql, params, many, context)
  File "/Users/huoyinghui/workspaces/drf3_opsweb/lib/python3.6/site-packages/django/db/backends/utils.py", line 85, in _execute
    return self.cursor.execute(sql, params)
  File "/Users/huoyinghui/workspaces/drf3_opsweb/lib/python3.6/site-packages/django/db/utils.py", line 89, in __exit__
    raise dj_exc_value.with_traceback(traceback) from exc_value
  File "/Users/huoyinghui/workspaces/drf3_opsweb/lib/python3.6/site-packages/django/db/backends/utils.py", line 85, in _execute
    return self.cursor.execute(sql, params)
  File "/Users/huoyinghui/workspaces/drf3_opsweb/lib/python3.6/site-packages/django/db/backends/mysql/base.py", line 71, in execute
    return self.cursor.execute(query, args)
  File "/Users/huoyinghui/workspaces/drf3_opsweb/lib/python3.6/site-packages/pymysql/cursors.py", line 170, in execute
    result = self._query(query)
  File "/Users/huoyinghui/workspaces/drf3_opsweb/lib/python3.6/site-packages/pymysql/cursors.py", line 328, in _query
    conn.query(q)
  File "/Users/huoyinghui/workspaces/drf3_opsweb/lib/python3.6/site-packages/pymysql/connections.py", line 516, in query
    self._affected_rows = self._read_query_result(unbuffered=unbuffered)
  File "/Users/huoyinghui/workspaces/drf3_opsweb/lib/python3.6/site-packages/pymysql/connections.py", line 727, in _read_query_result
    result.read()
  File "/Users/huoyinghui/workspaces/drf3_opsweb/lib/python3.6/site-packages/pymysql/connections.py", line 1066, in read
    first_packet = self.connection._read_packet()
  File "/Users/huoyinghui/workspaces/drf3_opsweb/lib/python3.6/site-packages/pymysql/connections.py", line 683, in _read_packet
    packet.check_error()
  File "/Users/huoyinghui/workspaces/drf3_opsweb/lib/python3.6/site-packages/pymysql/protocol.py", line 220, in check_error
    err.raise_mysql_exception(self._data)
  File "/Users/huoyinghui/workspaces/drf3_opsweb/lib/python3.6/site-packages/pymysql/err.py", line 109, in raise_mysql_exception
    raise errorclass(errno, errval)
django.db.utils.ProgrammingError: (1146, "Table 'opsweb.xadmin_usersettings' doesn't exist")
2019-07-29 18:36:15 [django.request:228] [WARNING] - Not Found: /
2019-07-29 18:36:20 [django.request:228] [ERROR] - Internal Server Error: /xadmin/
Traceback (most recent call last):
  File "/Users/huoyinghui/workspaces/drf3_opsweb/lib/python3.6/site-packages/django/db/backends/utils.py", line 85, in _execute
    return self.cursor.execute(sql, params)
  File "/Users/huoyinghui/workspaces/drf3_opsweb/lib/python3.6/site-packages/django/db/backends/mysql/base.py", line 71, in execute
    return self.cursor.execute(query, args)
  File "/Users/huoyinghui/workspaces/drf3_opsweb/lib/python3.6/site-packages/pymysql/cursors.py", line 170, in execute
    result = self._query(query)
  File "/Users/huoyinghui/workspaces/drf3_opsweb/lib/python3.6/site-packages/pymysql/cursors.py", line 328, in _query
    conn.query(q)
  File "/Users/huoyinghui/workspaces/drf3_opsweb/lib/python3.6/site-packages/pymysql/connections.py", line 516, in query
    self._affected_rows = self._read_query_result(unbuffered=unbuffered)
  File "/Users/huoyinghui/workspaces/drf3_opsweb/lib/python3.6/site-packages/pymysql/connections.py", line 727, in _read_query_result
    result.read()
  File "/Users/huoyinghui/workspaces/drf3_opsweb/lib/python3.6/site-packages/pymysql/connections.py", line 1066, in read
    first_packet = self.connection._read_packet()
  File "/Users/huoyinghui/workspaces/drf3_opsweb/lib/python3.6/site-packages/pymysql/connections.py", line 683, in _read_packet
    packet.check_error()
  File "/Users/huoyinghui/workspaces/drf3_opsweb/lib/python3.6/site-packages/pymysql/protocol.py", line 220, in check_error
    err.raise_mysql_exception(self._data)
  File "/Users/huoyinghui/workspaces/drf3_opsweb/lib/python3.6/site-packages/pymysql/err.py", line 109, in raise_mysql_exception
    raise errorclass(errno, errval)
pymysql.err.ProgrammingError: (1146, "Table 'opsweb.xadmin_usersettings' doesn't exist")

The above exception was the direct cause of the following exception:

Traceback (most recent call last):
  File "/Users/huoyinghui/workspaces/drf3_opsweb/lib/python3.6/site-packages/django/core/handlers/exception.py", line 34, in inner
    response = get_response(request)
  File "/Users/huoyinghui/workspaces/drf3_opsweb/lib/python3.6/site-packages/django/core/handlers/base.py", line 126, in _get_response
    response = self.process_exception_by_middleware(e, request)
  File "/Users/huoyinghui/workspaces/drf3_opsweb/lib/python3.6/site-packages/django/core/handlers/base.py", line 124, in _get_response
    response = wrapped_callback(request, *callback_args, **callback_kwargs)
  File "/Users/huoyinghui/workspaces/drf3_opsweb/lib/python3.6/site-packages/xadmin/sites.py", line 300, in wrapper
    return self.admin_view(view, cacheable)(*args, **kwargs)
  File "/Users/huoyinghui/workspaces/drf3_opsweb/lib/python3.6/site-packages/django/views/decorators/cache.py", line 44, in _wrapped_view_func
    response = view_func(request, *args, **kwargs)
  File "/Users/huoyinghui/workspaces/drf3_opsweb/lib/python3.6/site-packages/xadmin/sites.py", line 208, in inner
    return view(request, *args, **kwargs)
  File "/Users/huoyinghui/workspaces/drf3_opsweb/lib/python3.6/site-packages/xadmin/views/base.py", line 282, in view
    return handler(request, *args, **kwargs)
  File "/Users/huoyinghui/workspaces/drf3_opsweb/lib/python3.6/site-packages/django/views/decorators/cache.py", line 44, in _wrapped_view_func
    response = view_func(request, *args, **kwargs)
  File "/Users/huoyinghui/workspaces/drf3_opsweb/lib/python3.6/site-packages/xadmin/views/dashboard.py", line 592, in get
    self.widgets = self.get_widgets()
  File "/Users/huoyinghui/workspaces/drf3_opsweb/lib/python3.6/site-packages/xadmin/views/base.py", line 80, in method
    return filter_chain(filters, len(filters) - 1, _inner_method, *args, **kwargs)
  File "/Users/huoyinghui/workspaces/drf3_opsweb/lib/python3.6/site-packages/xadmin/views/base.py", line 49, in filter_chain
    return func()
  File "/Users/huoyinghui/workspaces/drf3_opsweb/lib/python3.6/site-packages/xadmin/views/base.py", line 74, in _inner_method
    return func(self, *args, **kwargs)
  File "/Users/huoyinghui/workspaces/drf3_opsweb/lib/python3.6/site-packages/xadmin/views/dashboard.py", line 549, in get_widgets
    if len(portal_pos):
  File "/Users/huoyinghui/workspaces/drf3_opsweb/lib/python3.6/site-packages/django/db/models/query.py", line 250, in __len__
    self._fetch_all()
  File "/Users/huoyinghui/workspaces/drf3_opsweb/lib/python3.6/site-packages/django/db/models/query.py", line 1183, in _fetch_all
    self._result_cache = list(self._iterable_class(self))
  File "/Users/huoyinghui/workspaces/drf3_opsweb/lib/python3.6/site-packages/django/db/models/query.py", line 54, in __iter__
    results = compiler.execute_sql(chunked_fetch=self.chunked_fetch, chunk_size=self.chunk_size)
  File "/Users/huoyinghui/workspaces/drf3_opsweb/lib/python3.6/site-packages/django/db/models/sql/compiler.py", line 1061, in execute_sql
    cursor.execute(sql, params)
  File "/Users/huoyinghui/workspaces/drf3_opsweb/lib/python3.6/site-packages/django/db/backends/utils.py", line 100, in execute
    return super().execute(sql, params)
  File "/Users/huoyinghui/workspaces/drf3_opsweb/lib/python3.6/site-packages/django/db/backends/utils.py", line 68, in execute
    return self._execute_with_wrappers(sql, params, many=False, executor=self._execute)
  File "/Users/huoyinghui/workspaces/drf3_opsweb/lib/python3.6/site-packages/django/db/backends/utils.py", line 77, in _execute_with_wrappers
    return executor(sql, params, many, context)
  File "/Users/huoyinghui/workspaces/drf3_opsweb/lib/python3.6/site-packages/django/db/backends/utils.py", line 85, in _execute
    return self.cursor.execute(sql, params)
  File "/Users/huoyinghui/workspaces/drf3_opsweb/lib/python3.6/site-packages/django/db/utils.py", line 89, in __exit__
    raise dj_exc_value.with_traceback(traceback) from exc_value
  File "/Users/huoyinghui/workspaces/drf3_opsweb/lib/python3.6/site-packages/django/db/backends/utils.py", line 85, in _execute
    return self.cursor.execute(sql, params)
  File "/Users/huoyinghui/workspaces/drf3_opsweb/lib/python3.6/site-packages/django/db/backends/mysql/base.py", line 71, in execute
    return self.cursor.execute(query, args)
  File "/Users/huoyinghui/workspaces/drf3_opsweb/lib/python3.6/site-packages/pymysql/cursors.py", line 170, in execute
    result = self._query(query)
  File "/Users/huoyinghui/workspaces/drf3_opsweb/lib/python3.6/site-packages/pymysql/cursors.py", line 328, in _query
    conn.query(q)
  File "/Users/huoyinghui/workspaces/drf3_opsweb/lib/python3.6/site-packages/pymysql/connections.py", line 516, in query
    self._affected_rows = self._read_query_result(unbuffered=unbuffered)
  File "/Users/huoyinghui/workspaces/drf3_opsweb/lib/python3.6/site-packages/pymysql/connections.py", line 727, in _read_query_result
    result.read()
  File "/Users/huoyinghui/workspaces/drf3_opsweb/lib/python3.6/site-packages/pymysql/connections.py", line 1066, in read
    first_packet = self.connection._read_packet()
  File "/Users/huoyinghui/workspaces/drf3_opsweb/lib/python3.6/site-packages/pymysql/connections.py", line 683, in _read_packet
    packet.check_error()
  File "/Users/huoyinghui/workspaces/drf3_opsweb/lib/python3.6/site-packages/pymysql/protocol.py", line 220, in check_error
    err.raise_mysql_exception(self._data)
  File "/Users/huoyinghui/workspaces/drf3_opsweb/lib/python3.6/site-packages/pymysql/err.py", line 109, in raise_mysql_exception
    raise errorclass(errno, errval)
django.db.utils.ProgrammingError: (1146, "Table 'opsweb.xadmin_usersettings' doesn't exist")
2019-07-30 14:20:14 [django.request:228] [WARNING] - Not Found: /
2019-07-30 14:20:14 [django.request:228] [WARNING] - Not Found: /favicon.ico
2019-07-30 14:21:27 [django.request:228] [WARNING] - Unauthorized: /api/core/user/
2019-07-30 14:21:56 [django.request:228] [WARNING] - Not Found: /favicon.ico
2019-07-30 15:15:08 [django.request:228] [WARNING] - Not Found: /favicon.ico
2019-07-30 15:27:07 [django.request:228] [WARNING] - Not Found: /favicon.ico
2019-07-30 16:02:44 [django.request:228] [WARNING] - Not Found: /favicon.ico
2019-07-30 16:05:18 [django.request:228] [WARNING] - Not Found: /favicon.ico
2019-07-30 16:26:46 [django.request:228] [WARNING] - Not Found: /favicon.ico
2019-07-30 16:34:00 [django.request:228] [WARNING] - Not Found: /favicon.ico
2019-07-30 16:34:54 [django.request:228] [WARNING] - Not Found: /favicon.ico
2019-07-30 16:35:27 [django.request:228] [WARNING] - Not Found: /favicon.ico
2019-07-30 16:52:42 [django.request:228] [WARNING] - Not Found: /admin/core/pagejson/
2019-07-30 17:00:38 [django.request:228] [WARNING] - Not Found: /xamdin
2019-07-30 17:08:55 [django.request:228] [ERROR] - Internal Server Error: /docs/
Traceback (most recent call last):
  File "/Users/huoyinghui/workspaces/drf3_opsweb/lib/python3.6/site-packages/django/core/handlers/exception.py", line 34, in inner
    response = get_response(request)
  File "/Users/huoyinghui/workspaces/drf3_opsweb/lib/python3.6/site-packages/django/core/handlers/base.py", line 126, in _get_response
    response = self.process_exception_by_middleware(e, request)
  File "/Users/huoyinghui/workspaces/drf3_opsweb/lib/python3.6/site-packages/django/core/handlers/base.py", line 124, in _get_response
    response = wrapped_callback(request, *callback_args, **callback_kwargs)
  File "/Users/huoyinghui/workspaces/drf3_opsweb/lib/python3.6/site-packages/django/views/decorators/csrf.py", line 54, in wrapped_view
    return view_func(*args, **kwargs)
  File "/Users/huoyinghui/workspaces/drf3_opsweb/lib/python3.6/site-packages/django/views/generic/base.py", line 68, in view
    return self.dispatch(request, *args, **kwargs)
  File "/Users/huoyinghui/workspaces/drf3_opsweb/lib/python3.6/site-packages/rest_framework/views.py", line 483, in dispatch
    response = self.handle_exception(exc)
  File "/Users/huoyinghui/workspaces/drf3_opsweb/lib/python3.6/site-packages/rest_framework/views.py", line 443, in handle_exception
    self.raise_uncaught_exception(exc)
  File "/Users/huoyinghui/workspaces/drf3_opsweb/lib/python3.6/site-packages/rest_framework/views.py", line 480, in dispatch
    response = handler(request, *args, **kwargs)
  File "/Users/huoyinghui/workspaces/drf3_opsweb/lib/python3.6/site-packages/rest_framework/schemas/views.py", line 31, in get
    schema = self.schema_generator.get_schema(request, self.public)
  File "/Users/huoyinghui/workspaces/drf3_opsweb/lib/python3.6/site-packages/rest_framework/schemas/generators.py", line 286, in get_schema
    links = self.get_links(None if public else request)
  File "/Users/huoyinghui/workspaces/drf3_opsweb/lib/python3.6/site-packages/rest_framework/schemas/generators.py", line 322, in get_links
    if not self.has_view_permissions(path, method, view):
  File "/Users/huoyinghui/workspaces/drf3_opsweb/lib/python3.6/site-packages/rest_framework/schemas/generators.py", line 397, in has_view_permissions
    view.check_permissions(view.request)
  File "/Users/huoyinghui/workspaces/drf3_opsweb/lib/python3.6/site-packages/rest_framework/views.py", line 322, in check_permissions
    if not permission.has_permission(request, self):
AttributeError: 'CustomAuth' object has no attribute 'has_permission'
2019-07-30 17:11:48 [django.request:228] [ERROR] - Internal Server Error: /docs/
Traceback (most recent call last):
  File "/Users/huoyinghui/workspaces/drf3_opsweb/lib/python3.6/site-packages/django/utils/module_loading.py", line 20, in import_string
    return getattr(module, class_name)
AttributeError: module 'core.views' has no attribute 'CustomBackend'

The above exception was the direct cause of the following exception:

Traceback (most recent call last):
  File "/Users/huoyinghui/workspaces/drf3_opsweb/lib/python3.6/site-packages/django/core/handlers/exception.py", line 34, in inner
    response = get_response(request)
  File "/Users/huoyinghui/workspaces/drf3_opsweb/lib/python3.6/site-packages/django/core/handlers/base.py", line 126, in _get_response
    response = self.process_exception_by_middleware(e, request)
  File "/Users/huoyinghui/workspaces/drf3_opsweb/lib/python3.6/site-packages/django/core/handlers/base.py", line 124, in _get_response
    response = wrapped_callback(request, *callback_args, **callback_kwargs)
  File "/Users/huoyinghui/workspaces/drf3_opsweb/lib/python3.6/site-packages/django/views/decorators/csrf.py", line 54, in wrapped_view
    return view_func(*args, **kwargs)
  File "/Users/huoyinghui/workspaces/drf3_opsweb/lib/python3.6/site-packages/django/views/generic/base.py", line 68, in view
    return self.dispatch(request, *args, **kwargs)
  File "/Users/huoyinghui/workspaces/drf3_opsweb/lib/python3.6/site-packages/rest_framework/views.py", line 483, in dispatch
    response = self.handle_exception(exc)
  File "/Users/huoyinghui/workspaces/drf3_opsweb/lib/python3.6/site-packages/rest_framework/views.py", line 443, in handle_exception
    self.raise_uncaught_exception(exc)
  File "/Users/huoyinghui/workspaces/drf3_opsweb/lib/python3.6/site-packages/rest_framework/views.py", line 471, in dispatch
    self.initial(request, *args, **kwargs)
  File "/Users/huoyinghui/workspaces/drf3_opsweb/lib/python3.6/site-packages/rest_framework/views.py", line 388, in initial
    self.perform_authentication(request)
  File "/Users/huoyinghui/workspaces/drf3_opsweb/lib/python3.6/site-packages/rest_framework/views.py", line 314, in perform_authentication
    request.user
  File "/Users/huoyinghui/workspaces/drf3_opsweb/lib/python3.6/site-packages/rest_framework/request.py", line 222, in user
    self._authenticate()
  File "/Users/huoyinghui/workspaces/drf3_opsweb/lib/python3.6/site-packages/rest_framework/request.py", line 375, in _authenticate
    user_auth_tuple = authenticator.authenticate(self)
  File "/Users/huoyinghui/workspaces/drf3_opsweb/lib/python3.6/site-packages/rest_framework/authentication.py", line 127, in authenticate
    if not user or not user.is_active:
  File "/Users/huoyinghui/workspaces/drf3_opsweb/lib/python3.6/site-packages/django/utils/functional.py", line 213, in inner
    self._setup()
  File "/Users/huoyinghui/workspaces/drf3_opsweb/lib/python3.6/site-packages/django/utils/functional.py", line 347, in _setup
    self._wrapped = self._setupfunc()
  File "/Users/huoyinghui/workspaces/drf3_opsweb/lib/python3.6/site-packages/django/contrib/auth/middleware.py", line 24, in <lambda>
    request.user = SimpleLazyObject(lambda: get_user(request))
  File "/Users/huoyinghui/workspaces/drf3_opsweb/lib/python3.6/site-packages/django/contrib/auth/middleware.py", line 12, in get_user
    request._cached_user = auth.get_user(request)
  File "/Users/huoyinghui/workspaces/drf3_opsweb/lib/python3.6/site-packages/django/contrib/auth/__init__.py", line 188, in get_user
    backend = load_backend(backend_path)
  File "/Users/huoyinghui/workspaces/drf3_opsweb/lib/python3.6/site-packages/django/contrib/auth/__init__.py", line 21, in load_backend
    return import_string(path)()
  File "/Users/huoyinghui/workspaces/drf3_opsweb/lib/python3.6/site-packages/django/utils/module_loading.py", line 24, in import_string
    ) from err
ImportError: Module "core.views" does not define a "CustomBackend" attribute/class
2019-07-30 17:11:55 [django.request:228] [ERROR] - Internal Server Error: /docs/
Traceback (most recent call last):
  File "/Users/huoyinghui/workspaces/drf3_opsweb/lib/python3.6/site-packages/django/utils/module_loading.py", line 20, in import_string
    return getattr(module, class_name)
AttributeError: module 'core.views' has no attribute 'CustomBackend'

The above exception was the direct cause of the following exception:

Traceback (most recent call last):
  File "/Users/huoyinghui/workspaces/drf3_opsweb/lib/python3.6/site-packages/django/core/handlers/exception.py", line 34, in inner
    response = get_response(request)
  File "/Users/huoyinghui/workspaces/drf3_opsweb/lib/python3.6/site-packages/django/core/handlers/base.py", line 126, in _get_response
    response = self.process_exception_by_middleware(e, request)
  File "/Users/huoyinghui/workspaces/drf3_opsweb/lib/python3.6/site-packages/django/core/handlers/base.py", line 124, in _get_response
    response = wrapped_callback(request, *callback_args, **callback_kwargs)
  File "/Users/huoyinghui/workspaces/drf3_opsweb/lib/python3.6/site-packages/django/views/decorators/csrf.py", line 54, in wrapped_view
    return view_func(*args, **kwargs)
  File "/Users/huoyinghui/workspaces/drf3_opsweb/lib/python3.6/site-packages/django/views/generic/base.py", line 68, in view
    return self.dispatch(request, *args, **kwargs)
  File "/Users/huoyinghui/workspaces/drf3_opsweb/lib/python3.6/site-packages/rest_framework/views.py", line 483, in dispatch
    response = self.handle_exception(exc)
  File "/Users/huoyinghui/workspaces/drf3_opsweb/lib/python3.6/site-packages/rest_framework/views.py", line 443, in handle_exception
    self.raise_uncaught_exception(exc)
  File "/Users/huoyinghui/workspaces/drf3_opsweb/lib/python3.6/site-packages/rest_framework/views.py", line 471, in dispatch
    self.initial(request, *args, **kwargs)
  File "/Users/huoyinghui/workspaces/drf3_opsweb/lib/python3.6/site-packages/rest_framework/views.py", line 388, in initial
    self.perform_authentication(request)
  File "/Users/huoyinghui/workspaces/drf3_opsweb/lib/python3.6/site-packages/rest_framework/views.py", line 314, in perform_authentication
    request.user
  File "/Users/huoyinghui/workspaces/drf3_opsweb/lib/python3.6/site-packages/rest_framework/request.py", line 222, in user
    self._authenticate()
  File "/Users/huoyinghui/workspaces/drf3_opsweb/lib/python3.6/site-packages/rest_framework/request.py", line 375, in _authenticate
    user_auth_tuple = authenticator.authenticate(self)
  File "/Users/huoyinghui/workspaces/drf3_opsweb/lib/python3.6/site-packages/rest_framework/authentication.py", line 127, in authenticate
    if not user or not user.is_active:
  File "/Users/huoyinghui/workspaces/drf3_opsweb/lib/python3.6/site-packages/django/utils/functional.py", line 213, in inner
    self._setup()
  File "/Users/huoyinghui/workspaces/drf3_opsweb/lib/python3.6/site-packages/django/utils/functional.py", line 347, in _setup
    self._wrapped = self._setupfunc()
  File "/Users/huoyinghui/workspaces/drf3_opsweb/lib/python3.6/site-packages/django/contrib/auth/middleware.py", line 24, in <lambda>
    request.user = SimpleLazyObject(lambda: get_user(request))
  File "/Users/huoyinghui/workspaces/drf3_opsweb/lib/python3.6/site-packages/django/contrib/auth/middleware.py", line 12, in get_user
    request._cached_user = auth.get_user(request)
  File "/Users/huoyinghui/workspaces/drf3_opsweb/lib/python3.6/site-packages/django/contrib/auth/__init__.py", line 188, in get_user
    backend = load_backend(backend_path)
  File "/Users/huoyinghui/workspaces/drf3_opsweb/lib/python3.6/site-packages/django/contrib/auth/__init__.py", line 21, in load_backend
    return import_string(path)()
  File "/Users/huoyinghui/workspaces/drf3_opsweb/lib/python3.6/site-packages/django/utils/module_loading.py", line 24, in import_string
    ) from err
ImportError: Module "core.views" does not define a "CustomBackend" attribute/class
2019-07-30 17:12:29 [django.request:228] [WARNING] - Unauthorized: /api/core/user/
2019-07-30 17:25:04 [django.request:228] [ERROR] - Internal Server Error: /api/core/tree/
Traceback (most recent call last):
  File "/Users/huoyinghui/workspaces/drf3_opsweb/lib/python3.6/site-packages/django/core/handlers/exception.py", line 34, in inner
    response = get_response(request)
  File "/Users/huoyinghui/workspaces/drf3_opsweb/lib/python3.6/site-packages/django/core/handlers/base.py", line 126, in _get_response
    response = self.process_exception_by_middleware(e, request)
  File "/Users/huoyinghui/workspaces/drf3_opsweb/lib/python3.6/site-packages/django/core/handlers/base.py", line 124, in _get_response
    response = wrapped_callback(request, *callback_args, **callback_kwargs)
  File "/Users/huoyinghui/workspaces/drf3_opsweb/lib/python3.6/site-packages/django/views/decorators/csrf.py", line 54, in wrapped_view
    return view_func(*args, **kwargs)
  File "/Users/huoyinghui/workspaces/drf3_opsweb/lib/python3.6/site-packages/rest_framework/viewsets.py", line 103, in view
    return self.dispatch(request, *args, **kwargs)
  File "/Users/huoyinghui/workspaces/drf3_opsweb/lib/python3.6/site-packages/rest_framework/views.py", line 483, in dispatch
    response = self.handle_exception(exc)
  File "/Users/huoyinghui/workspaces/drf3_opsweb/lib/python3.6/site-packages/rest_framework/views.py", line 443, in handle_exception
    self.raise_uncaught_exception(exc)
  File "/Users/huoyinghui/workspaces/drf3_opsweb/lib/python3.6/site-packages/rest_framework/views.py", line 480, in dispatch
    response = handler(request, *args, **kwargs)
  File "/Users/huoyinghui/github/docker_nginx/opsweb/core/views.py", line 84, in list
    page = get_page_json_tree(page)
TypeError: get_page_json_tree() takes 0 positional arguments but 1 was given
2019-07-30 18:42:55 [django.request:228] [WARNING] - Not Found: /
2019-07-30 18:42:55 [django.request:228] [WARNING] - Not Found: /favicon.ico
2019-07-30 18:43:00 [django.request:228] [ERROR] - Internal Server Error: /docs/
Traceback (most recent call last):
  File "/Users/huoyinghui/workspaces/drf3_opsweb/lib/python3.6/site-packages/django/urls/base.py", line 75, in reverse
    extra, resolver = resolver.namespace_dict[ns]
KeyError: 'rest_framework'

During handling of the above exception, another exception occurred:

Traceback (most recent call last):
  File "/Users/huoyinghui/workspaces/drf3_opsweb/lib/python3.6/site-packages/django/core/handlers/exception.py", line 34, in inner
    response = get_response(request)
  File "/Users/huoyinghui/workspaces/drf3_opsweb/lib/python3.6/site-packages/django/core/handlers/base.py", line 156, in _get_response
    response = self.process_exception_by_middleware(e, request)
  File "/Users/huoyinghui/workspaces/drf3_opsweb/lib/python3.6/site-packages/django/core/handlers/base.py", line 154, in _get_response
    response = response.render()
  File "/Users/huoyinghui/workspaces/drf3_opsweb/lib/python3.6/site-packages/django/template/response.py", line 106, in render
    self.content = self.rendered_content
  File "/Users/huoyinghui/workspaces/drf3_opsweb/lib/python3.6/site-packages/rest_framework/response.py", line 72, in rendered_content
    ret = renderer.render(self.data, accepted_media_type, context)
  File "/Users/huoyinghui/workspaces/drf3_opsweb/lib/python3.6/site-packages/rest_framework_swagger/renderers.py", line 54, in render
    self.set_context(data, renderer_context)
  File "/Users/huoyinghui/workspaces/drf3_opsweb/lib/python3.6/site-packages/rest_framework_swagger/renderers.py", line 64, in set_context
    renderer_context.update(self.get_auth_urls())
  File "/Users/huoyinghui/workspaces/drf3_opsweb/lib/python3.6/site-packages/rest_framework_swagger/renderers.py", line 76, in get_auth_urls
    urls['LOGIN_URL'] = resolve_url(settings.LOGIN_URL)
  File "/Users/huoyinghui/workspaces/drf3_opsweb/lib/python3.6/site-packages/django/shortcuts.py", line 148, in resolve_url
    return reverse(to, args=args, kwargs=kwargs)
  File "/Users/huoyinghui/workspaces/drf3_opsweb/lib/python3.6/site-packages/django/urls/base.py", line 86, in reverse
    raise NoReverseMatch("%s is not a registered namespace" % key)
django.urls.exceptions.NoReverseMatch: 'rest_framework' is not a registered namespace
2019-07-30 18:43:59 [django.request:228] [WARNING] - Forbidden: /docs/
2019-07-30 18:44:22 [django.request:228] [WARNING] - Forbidden: /api-token-auth/
2019-07-31 15:22:35 [django.request:228] [WARNING] - Not Found: /
2019-07-31 15:22:35 [django.request:228] [WARNING] - Not Found: /favicon.ico
2019-07-31 16:06:17 [django.request:228] [ERROR] - Internal Server Error: /docs/
Traceback (most recent call last):
  File "/Users/huoyinghui/workspaces/drf3_opsweb/lib/python3.6/site-packages/django/urls/base.py", line 75, in reverse
    extra, resolver = resolver.namespace_dict[ns]
KeyError: 'rest_framework'

During handling of the above exception, another exception occurred:

Traceback (most recent call last):
  File "/Users/huoyinghui/workspaces/drf3_opsweb/lib/python3.6/site-packages/django/core/handlers/exception.py", line 34, in inner
    response = get_response(request)
  File "/Users/huoyinghui/workspaces/drf3_opsweb/lib/python3.6/site-packages/django/core/handlers/base.py", line 156, in _get_response
    response = self.process_exception_by_middleware(e, request)
  File "/Users/huoyinghui/workspaces/drf3_opsweb/lib/python3.6/site-packages/django/core/handlers/base.py", line 154, in _get_response
    response = response.render()
  File "/Users/huoyinghui/workspaces/drf3_opsweb/lib/python3.6/site-packages/django/template/response.py", line 106, in render
    self.content = self.rendered_content
  File "/Users/huoyinghui/workspaces/drf3_opsweb/lib/python3.6/site-packages/rest_framework/response.py", line 72, in rendered_content
    ret = renderer.render(self.data, accepted_media_type, context)
  File "/Users/huoyinghui/workspaces/drf3_opsweb/lib/python3.6/site-packages/rest_framework_swagger/renderers.py", line 54, in render
    self.set_context(data, renderer_context)
  File "/Users/huoyinghui/workspaces/drf3_opsweb/lib/python3.6/site-packages/rest_framework_swagger/renderers.py", line 64, in set_context
    renderer_context.update(self.get_auth_urls())
  File "/Users/huoyinghui/workspaces/drf3_opsweb/lib/python3.6/site-packages/rest_framework_swagger/renderers.py", line 76, in get_auth_urls
    urls['LOGIN_URL'] = resolve_url(settings.LOGIN_URL)
  File "/Users/huoyinghui/workspaces/drf3_opsweb/lib/python3.6/site-packages/django/shortcuts.py", line 148, in resolve_url
    return reverse(to, args=args, kwargs=kwargs)
  File "/Users/huoyinghui/workspaces/drf3_opsweb/lib/python3.6/site-packages/django/urls/base.py", line 86, in reverse
    raise NoReverseMatch("%s is not a registered namespace" % key)
django.urls.exceptions.NoReverseMatch: 'rest_framework' is not a registered namespace
2019-07-31 16:11:14 [django.request:228] [WARNING] - Not Found: /docs/
2019-07-31 16:11:16 [django.request:228] [WARNING] - Not Found: /docs/
2019-07-31 16:11:21 [django.request:228] [WARNING] - Not Found: /
2019-07-31 16:14:33 [django.request:228] [WARNING] - Unauthorized: /api/music/
2019-07-31 16:14:33 [django.request:228] [WARNING] - Not Found: /favicon.ico
2019-07-31 16:15:19 [django.request:228] [WARNING] - Unauthorized: /api/music/
2019-07-31 16:15:19 [django.request:228] [WARNING] - Not Found: /favicon.ico
2019-07-31 16:15:36 [django.request:228] [WARNING] - Not Found: /api/music.
2019-07-31 16:16:22 [django.request:228] [WARNING] - Unauthorized: /api/music/
2019-07-31 16:17:40 [django.request:228] [WARNING] - Unauthorized: /api/music/
2019-07-31 16:27:10 [django.request:228] [WARNING] - Unauthorized: /api/share/
2019-07-31 16:27:13 [django.request:228] [WARNING] - Unauthorized: /api/share/
2019-07-31 16:27:15 [django.request:228] [WARNING] - Unauthorized: /api/share/
2019-07-31 16:28:47 [django.request:228] [WARNING] - Unauthorized: /api/share/
2019-07-31 16:29:04 [django.request:228] [WARNING] - Unauthorized: /api/share/
2019-07-31 16:31:05 [django.request:228] [WARNING] - Unauthorized: /api/share/
2019-07-31 16:33:44 [django.request:228] [WARNING] - Unauthorized: /api/share/
2019-07-31 16:51:30 [django.request:228] [ERROR] - Internal Server Error: /api/share/1/detail/
Traceback (most recent call last):
  File "/Users/huoyinghui/workspaces/drf3_opsweb/lib/python3.6/site-packages/django/core/handlers/exception.py", line 34, in inner
    response = get_response(request)
  File "/Users/huoyinghui/workspaces/drf3_opsweb/lib/python3.6/site-packages/django/core/handlers/base.py", line 126, in _get_response
    response = self.process_exception_by_middleware(e, request)
  File "/Users/huoyinghui/workspaces/drf3_opsweb/lib/python3.6/site-packages/django/core/handlers/base.py", line 124, in _get_response
    response = wrapped_callback(request, *callback_args, **callback_kwargs)
  File "/Users/huoyinghui/workspaces/drf3_opsweb/lib/python3.6/site-packages/django/views/decorators/csrf.py", line 54, in wrapped_view
    return view_func(*args, **kwargs)
  File "/Users/huoyinghui/workspaces/drf3_opsweb/lib/python3.6/site-packages/rest_framework/viewsets.py", line 103, in view
    return self.dispatch(request, *args, **kwargs)
  File "/Users/huoyinghui/workspaces/drf3_opsweb/lib/python3.6/site-packages/rest_framework/views.py", line 483, in dispatch
    response = self.handle_exception(exc)
  File "/Users/huoyinghui/workspaces/drf3_opsweb/lib/python3.6/site-packages/rest_framework/views.py", line 443, in handle_exception
    self.raise_uncaught_exception(exc)
  File "/Users/huoyinghui/workspaces/drf3_opsweb/lib/python3.6/site-packages/rest_framework/views.py", line 480, in dispatch
    response = handler(request, *args, **kwargs)
TypeError: 'bool' object is not callable
2019-07-31 16:51:45 [django.request:228] [ERROR] - Internal Server Error: /api/share/1/detail/
Traceback (most recent call last):
  File "/Users/huoyinghui/workspaces/drf3_opsweb/lib/python3.6/site-packages/django/core/handlers/exception.py", line 34, in inner
    response = get_response(request)
  File "/Users/huoyinghui/workspaces/drf3_opsweb/lib/python3.6/site-packages/django/core/handlers/base.py", line 126, in _get_response
    response = self.process_exception_by_middleware(e, request)
  File "/Users/huoyinghui/workspaces/drf3_opsweb/lib/python3.6/site-packages/django/core/handlers/base.py", line 124, in _get_response
    response = wrapped_callback(request, *callback_args, **callback_kwargs)
  File "/Users/huoyinghui/workspaces/drf3_opsweb/lib/python3.6/site-packages/django/views/decorators/csrf.py", line 54, in wrapped_view
    return view_func(*args, **kwargs)
  File "/Users/huoyinghui/workspaces/drf3_opsweb/lib/python3.6/site-packages/rest_framework/viewsets.py", line 103, in view
    return self.dispatch(request, *args, **kwargs)
  File "/Users/huoyinghui/workspaces/drf3_opsweb/lib/python3.6/site-packages/rest_framework/views.py", line 483, in dispatch
    response = self.handle_exception(exc)
  File "/Users/huoyinghui/workspaces/drf3_opsweb/lib/python3.6/site-packages/rest_framework/views.py", line 443, in handle_exception
    self.raise_uncaught_exception(exc)
  File "/Users/huoyinghui/workspaces/drf3_opsweb/lib/python3.6/site-packages/rest_framework/views.py", line 480, in dispatch
    response = handler(request, *args, **kwargs)
TypeError: 'bool' object is not callable
2019-07-31 17:09:21 [django.request:228] [WARNING] - Not Found: /xadmin
2019-07-31 17:09:21 [django.request:228] [WARNING] - Not Found: /favicon.ico
2019-07-31 17:09:24 [django.request:228] [WARNING] - Not Found: /admin
